<?xml version="1.0"?>
<robot xmlns:xacro="http://www.ros.org/wiki/xacro">

    <link name="can_gripper_cr">
        <visual>
            <origin xyz="0.0 0 0.0" rpy="0 0 1.57" />
            <geometry>
                <box size="0.05 0.02 0.02"/>
            </geometry>
            <material name="blue">
                <color rgba="0.0 0.0 1.0 1.0"/>
            </material>
        </visual>
        <collision>
            <origin xyz="0.00 0 0.00" rpy="0 0 1.57" />
            <geometry>
                <box size="0.05 0.02 0.02"/>
            </geometry>
        </collision>
        <xacro:inertial_box mass="0.01" x="0.05" y="0.02" z="0.02">
            <origin xyz="0.0 0 0" rpy="0 0 0"/>
        </xacro:inertial_box>
    </link>

    <joint name="can_gripper_joint_cr" type="prismatic">
        <parent link="can_lift_link"/>
        <child link="can_gripper_cr"/>
        <origin xyz="0.09 -0.05 0.0" rpy="0 0 0"/>
        <axis xyz="1 0 0"/>
        <limit effort="1000.0" lower="0" upper="0.04" velocity="0.5"/>
    </joint>

    <link name="can_gripper_cl">
        <visual>
            <origin xyz="0.0 0 0" rpy="0 0 -1.57" />
            <geometry>
                <box size="0.05 0.02 0.02"/>
            </geometry>
            <material name="blue">
                <color rgba="0.0 0.0 1.0 1.0"/>
            </material>
        </visual>
        <collision>
            <origin xyz="0.0 0 0.0" rpy="0 0 -1.57" />
            <geometry>
                <box size="0.05 0.02 0.02"/>
            </geometry>
        </collision>
        <xacro:inertial_box mass="0.01" x="0.05" y="0.02" z="0.02">
            <origin xyz="0.0 0 0" rpy="0 0 0"/>
        </xacro:inertial_box>
    </link>

    <joint name="can_gripper_joint_cl" type="prismatic">
        <parent link="can_lift_link"/>
        <child link="can_gripper_cl"/>
        <origin xyz="0.09 0.05 0.0" rpy="0 0 0"/>
        <axis xyz="1 0 0"/>
        <limit effort="1000.0" lower="0" upper="0.04" velocity="0.5"/>
    </joint>

    <link name="can_gripper_sl">
        <visual>
            <origin xyz="0.0 0 0" rpy="0 0 -1.57" />
            <geometry>
                <box size="0.05 0.02 0.02"/>
            </geometry>
            <material name="blue">
                <color rgba="0.0 0.0 1.0 1.0"/>
            </material>
        </visual>
        <collision>
            <origin xyz="0.0 0 0.0" rpy="0 0 -1.57" />
            <geometry>
                <box size="0.05 0.02 0.02"/>
            </geometry>
        </collision>
        <xacro:inertial_box mass="0.01" x="0.05" y="0.02" z="0.02">
            <origin xyz="0.0 0 0" rpy="0 0 0"/>
        </xacro:inertial_box>
    </link>

    <joint name="can_gripper_joint_sl" type="prismatic">
        <parent link="body"/>
        <child link="can_gripper_sl"/>
        <origin xyz="0.13 0.15 0.08" rpy="0 0 0"/>
        <axis xyz="0 0 1"/>
        <limit effort="1000.0" lower="0" upper="0.01" velocity="0.5"/>
    </joint>

    <link name="can_gripper_sr">
        <visual>
            <origin xyz="0.0 0 0" rpy="0 0 -1.57" />
            <geometry>
                <box size="0.05 0.02 0.02"/>
            </geometry>
            <material name="blue">
                <color rgba="0.0 0.0 1.0 1.0"/>
            </material>
        </visual>
        <collision>
            <origin xyz="0.0 0 0.0" rpy="0 0 -1.57" />
            <geometry>
                <box size="0.05 0.02 0.02"/>
            </geometry>
        </collision>
        <xacro:inertial_box mass="0.01" x="0.05" y="0.02" z="0.02">
            <origin xyz="0.0 0 0" rpy="0 0 0"/>
        </xacro:inertial_box>
    </link>

    <joint name="can_gripper_joint_sr" type="prismatic">
        <parent link="body"/>
        <child link="can_gripper_sr"/>
        <origin xyz="0.13 -0.15 0.08" rpy="0 0 0"/>
        <axis xyz="0 0 1"/>
        <limit effort="1000.0" lower="0" upper="0.01" velocity="0.5"/>
    </joint>

    <gazebo>
        <plugin name="gripper_plugin_gz::DynamicDetachableJoint" filename="libgripper_plugin_gz.so">
            <parent_link>can_gripper_cl</parent_link>
            <attach_topic>/detachable_jointcl/attach</attach_topic>
            <detach_topic>/detachable_jointcl/detach</detach_topic>
            <output_topic>/detachable_jointcl/output</output_topic>
            <grip_link>grip_link</grip_link>
        </plugin>
        <plugin name="gripper_plugin_gz::DynamicDetachableJoint" filename="libgripper_plugin_gz.so">
            <parent_link>can_gripper_cr</parent_link>
            <attach_topic>/detachable_jointcr/attach</attach_topic>
            <detach_topic>/detachable_jointcr/detach</detach_topic>
            <output_topic>/detachable_jointcr/output</output_topic>
            <grip_link>grip_link</grip_link>
        </plugin>
        <plugin name="gripper_plugin_gz::DynamicDetachableJoint" filename="libgripper_plugin_gz.so">
            <parent_link>can_gripper_sl</parent_link>
            <attach_topic>/detachable_jointsl/attach</attach_topic>
            <detach_topic>/detachable_jointsl/detach</detach_topic>
            <output_topic>/detachable_jointsl/output</output_topic>
            <grip_link>grip_link</grip_link>
        </plugin>
        <plugin name="gripper_plugin_gz::DynamicDetachableJoint" filename="libgripper_plugin_gz.so">
            <parent_link>can_gripper_sr</parent_link>
            <attach_topic>/detachable_jointsr/attach</attach_topic>
            <detach_topic>/detachable_jointsr/detach</detach_topic>
            <output_topic>/detachable_jointsr/output</output_topic>
            <grip_link>grip_link</grip_link>
        </plugin>
        <plugin name="gripper_plugin_gz::DynamicDetachableJoint" filename="libgripper_plugin_gz.so">
            <parent_link>board_lift_link</parent_link>
            <attach_topic>/detachable_jointbd/attach</attach_topic>
            <detach_topic>/detachable_jointbd/detach</detach_topic>
            <output_topic>/detachable_jointbd/output</output_topic>
            <grip_link>grip_link</grip_link>
        </plugin>
    </gazebo>


</robot>

