<?xml version="1.0"?>
<robot xmlns:xacro="http://www.ros.org/wiki/xacro">

    <joint name="gripper_joint" type="prismatic">
        <parent link="body"/>
        <child link="gripper"/>
        <origin xyz="0.05 0 0.14"/>
        <axis xyz="1 0 0"/>
        <limit lower="0.0" upper="0.1" effort="10.0" velocity="1.0"/>
    </joint>


    <link name="gripper">        
        <visual>
            <geometry>
                <box size="0.1 0.03 0.03"/>
            </geometry>
            <material name="blue">
                <color rgba="0.0 0.0 1.0 1.0"/>
            </material>
        </visual>
        <collision>
            <geometry>
                <box size="0.1 0.03 0.03"/>
            </geometry>
        </collision>
        <xacro:inertial_box mass="0.1" x="0.1" y="0.03" z="0.03">
            <origin xyz="0 0 0" rpy="0 0 0"/>
        </xacro:inertial_box>
    </link>

</robot>