<?xml version="1.0"?>
<robot xmlns:xacro="http://www.ros.org/wiki/xacro">

    <!-- Prismatic Joint 1 (подъём доски) -->
    <link name="board_lift_link">
        <visual>
            <geometry>
                <box size="0.025 0.025 0.025"/>
            </geometry>
            <material name="red">
                <color rgba="1.0 0.0 0.0 1.0"/>
            </material>
        </visual>
        <xacro:inertial_box mass="0.2" x="0.025" y="0.025" z='0.025'>
            <origin xyz="0 0 0" rpy="0 0 0"/>
        </xacro:inertial_box>
    </link>

    <link name="board_lift_cube">
        <visual>
            <geometry>
                <box size="0.03 0.03 0.03"/>
            </geometry>
            <material name="blue">                     <!--захват доски прикрепленный к prismatic 1 и отвечающий за подъем доски-->
                <color rgba="0.0 0.0 1.0 1.0"/>
            </material>             
        </visual>
        <xacro:inertial_box mass="0.1" x="0.05" y="0.05" z='0.05'>
            <origin xyz="0 0 0" rpy="0 0 0"/>
        </xacro:inertial_box>
    </link>

    <joint name="board_lift_cube_joint" type="fixed">
        <parent link="board_lift_link"/>
        <child link="board_lift_cube"/>
        <origin xyz="0.14 0 0.015" rpy="0 0 0"/>
    </joint>

    <joint name="board_lift_joint" type="prismatic">
        <parent link="body"/>
        <child link="board_lift_link"/>
        <origin xyz="0 0 0.14" rpy="0 0 0"/>
        <axis xyz="0 0 1"/>
        <limit lower="0" upper="0.18" effort="30.0" velocity="0.5"/>
    </joint>

    <!-- Prismatic Joint 2 (подъём банок) -->
    <link name="can_lift_link">
        <visual>
            <geometry>
               <box size="0.025 0.025 0.025"/>
            </geometry>
            <material name="blue">
                <color rgba="0.0 0.0 1.0 1.0"/>
            </material>
        </visual>
        <xacro:inertial_box mass="0.2" x="0.025" y="0.025" z='0.025'>
            <origin xyz="0 0 0" rpy="0 0 0"/>
        </xacro:inertial_box>
    </link>

    <joint name="can_lift_joint" type="prismatic">
        <parent link="body"/>
        <child link="can_lift_link"/>
        <origin xyz="0.0 0.0 0.07" rpy="0 0 0"/>
        <axis xyz="0 0 1"/>
        <limit effort="30.0" lower="0" upper="0.2" velocity="0.5"/>
    </joint>

    <!-- Revolute Joint 1 (вращение банки 1) -->
    <!-- <link name="can_rotator_1_link">
        <visual>
            <geometry>
                <cylinder radius="0.015" length="0.02"/>
            </geometry>
            <material name="red">
                <color rgba="1.0 0.0 0.0 1.0"/>
            </material>
        </visual>
    </link> -->

    <!-- <link name="can_rotator_1_cube">
        <visual>
            <geometry>
                <box size="0.03 0.03 0.03"/>                      завхват банки №1
            </geometry>
            <material name="blue">
                <color rgba="0.0 0.0 1.0 1.0"/>
            </material>
        </visual>
        <xacro:inertial_box mass="0.1" x="0.05" y="0.05" z='0.05'>
            <origin xyz="0 0 0" rpy="0 0 0"/>
        </xacro:inertial_box>
    </link>

    <joint name="can_rotator_1_cube_joint" type="fixed">
        <parent link="can_rotator_1_link"/>
        <child link="can_rotator_1_cube"/>
        <origin xyz="0.05 0 0.05" rpy="0 0 0"/>
    </joint> -->



    <!-- Revolute Joint 2 (вращение банки 2) -->
    <!-- <link name="can_rotator_2_link">
        <visual>
            <geometry>
                <cylinder radius="0.015" length="0.02"/>
            </geometry>
            <material name="red">
                <color rgba="1.0 0.0 0.0 1.0"/>
            </material>
        </visual>
    </link> -->

    <!-- <link name="can_rotator_2_cube">
        <visual>
            <geometry>
                <box size="0.03 0.03 0.03"/>
            </geometry>
            <material name="blue">
                <color rgba="0.0 0.0 1.0 1.0"/>
            </material>                                                     завхват банки №2 
        </visual>
        <xacro:inertial_box mass="0.1" x="0.05" y="0.05" z='0.05'>
            <origin xyz="0 0 0" rpy="0 0 0"/>
        </xacro:inertial_box>
    </link>

    <joint name="can_rotator_2_cube_joint" type="fixed">
        <parent link="can_rotator_2_link"/>
        <child link="can_rotator_2_cube"/>
        <origin xyz="0.05 0 0.05" rpy="0 0 0"/>
    </joint> -->



      <gazebo>

        <plugin name="gz::sim::systems::JointStatePublisher" filename="gz-sim-joint-state-publisher-system">
            
            <!-- <joint_name>board_lift_joint</joint_name>
            <joint_name>can_lift_joint</joint_name>
            <joint_name>can_rotator_1_joint</joint_name>
            <joint_name>can_rotator_2_joint</joint_name> -->
        </plugin>

        <plugin name="gz::sim::systems::JointPositionController" filename="gz-sim-joint-position-controller-system">
            <topic>board_lift_topic</topic>
            <joint_name>board_lift_joint</joint_name>
            <!-- <joint_index>1</joint_index> -->
            <p_gain>2000.0</p_gain>
            <i_gain>0.1</i_gain>
            <d_gain>20.0</d_gain>
            <i_max>1</i_max>
            <i_min>-1</i_min>
            <cmd_max>20000</cmd_max>
            <cmd_min>-20000</cmd_min>
        </plugin>

        <plugin name="gz::sim::systems::JointPositionController" filename="gz-sim-joint-position-controller-system">
            <topic>can_lift_topic</topic> 
            <joint_name>can_lift_joint</joint_name> 
            <!-- <joint_index>1</joint_index> -->
            <p_gain>200</p_gain>
            <i_gain>1.0</i_gain>
            <d_gain>10.0</d_gain>
            <i_max>1</i_max>
            <i_min>-1</i_min>
            <cmd_max>20000</cmd_max>
            <cmd_min>-20000</cmd_min>
        </plugin>

        <plugin name="gz::sim::systems::JointPositionController" filename="gz-sim-joint-position-controller-system">
            <topic>can_rotator_1_topic</topic> 
            <joint_name>can_gripper_joint_cr</joint_name>
            <p_gain>10</p_gain>
            <i_gain>0.7</i_gain>
            <d_gain>0.01</d_gain>
            <i_max>5</i_max>
            <i_min>-5</i_min>
            <cmd_max>1000</cmd_max>
            <cmd_min>-1000</cmd_min>
        </plugin>

        <plugin name="gz::sim::systems::JointPositionController" filename="gz-sim-joint-position-controller-system">
            <topic>can_rotator_2_topic</topic> 
            <joint_name>can_gripper_joint_cl</joint_name>
            <p_gain>10</p_gain>
            <i_gain>0.7</i_gain>
            <d_gain>0.01</d_gain>
            <i_max>5</i_max>
            <i_min>-5</i_min>
            <cmd_max>1000</cmd_max>
            <cmd_min>-1000</cmd_min>
        </plugin>
    </gazebo>


</robot>